<?xml version="1.0"?>
<robot xmlns:xacro="http://www.ros.org/wiki/xacro">

    <xacro:include filename="inertial_macros.xacro"/>

    <!-- links and joints go here -->

    <!-- The rest of the robot can be described from base_link, which is the centre point of the four driving wheels -->
    <link name="base_link">
    </link>

    <!-- chassis joint goes here. It connects chassis to base_link via fixed joint -->
    <joint name="chassis_joint" type="fixed">
        <parent link="base_link"/>
        <child link="chassis"/>
        <origin xyz="0 0 0"/>
    </joint> launch-prefix="bash -c 'sleep 5; $0 $@'"
    <!-- chassis description goes here. It describes the chassis of the bot which is a 54cm x 54cm x 150cm box -->
    <link name="chassis">
        <visual>
            <!-- by default, the origin is centred around the link origin, so offset it by half the height -->
            <!-- <origin xyz="0 0 0.75" rpy="0 0 0"/> -->
            <geometry>
                <!-- <box size="0.54 0.54 1.5"/> -->
                <mesh filename="package://rbc_base/meshes/frame_ultra_low_poly.stl" scale="0.001 0.001 0.001"/>
                <!-- <mesh filename="model://frame_ultra_low_poly.stl"/> -->
            </geometry>
            <material name="white"/>
        </visual>
        <!-- physics model -->
        <collision>
            <origin xyz="0 0 0.77" rpy="0 0 0"/>
            <geometry>
                <cylinder length="1.54" radius="0.25"/>
            </geometry>
        </collision>
        <xacro:inertial_cylinder mass="20" length="1.54" radius="0.25">
            <origin xyz="0 0 0.77" rpy="0 0 0"/>
        </xacro:inertial_cylinder>
    </link>
    <joint name="laser_joint" type="fixed">
        <parent link="chassis"/>
        <child link="laser"/>
        <origin xyz="0 0 0.07" rpy="0 0 0"/>
    </joint>
    <link name="laser">
        <visual>
            <origin xyz="0 0 0" rpy="0 0 0"/>
            <geometry>
                <cylinder length="0.05" radius="0.05"/>
            </geometry>
            <material name="black"/>
        </visual>
    </link>
    <!-- gazebo specific description -->
    <gazebo reference="chassis">
        <material>Gazebo/White</material>
    </gazebo>

    <!-- WHEEL 1 (CLOCKWISE) -->
    <joint name="wheel_1_joint" type="continuous">
        <parent link="base_link"/>
        <child link="wheel_1"/>
        <origin xyz="0.2 0 0" rpy="0 -${pi/2} 0"/>
        <axis xyz="0 0 1"/>
    </joint>

    <link name="wheel_1">
        <visual>
            <geometry>      
                <cylinder length="0.038" radius="0.05" />
            </geometry>
            <material name="black"/>
        </visual>
        <collision>
            <geometry>      
                <cylinder length="0.038" radius="0.05" />
            </geometry>
        </collision>
        <xacro:inertial_cylinder mass="0.2" length="0.038" radius="0.05">
            <origin xyz="0 0 0" rpy="0 0 0"/>
        </xacro:inertial_cylinder>
    </link>

    <gazebo reference="wheel_1">
        <material>Gazebo/Black</material>
        <mu1 value="0.2"/>
        <mu2 value="1.5"/>
        <kp value="10000000.0" />
        <kd value="10000.0" />
        <fdir1 value="0 0 1"/>
        <maxContacts value= "1"/>
    </gazebo>

    <!-- WHEEL 2 -->
    <joint name="wheel_2_joint" type="continuous">
        <parent link="base_link"/>
        <child link="wheel_2"/>
        <origin xyz="-0.1 -0.1732050808 0" rpy="0 ${pi/2} ${pi/3}"/>
        <axis xyz="0 0 1"/>
    </joint>

    <link name="wheel_2">
        <visual>
            <geometry>      
                <cylinder length="0.038" radius="0.05" />
            </geometry>
            <material name="black"/>
        </visual>
        <collision>
            <geometry>      
                <cylinder length="0.038" radius="0.05" />
            </geometry>
        </collision>
        <xacro:inertial_cylinder mass="0.2" length="0.038" radius="0.05">
            <origin xyz="0 0 0" rpy="0 0 0"/>
        </xacro:inertial_cylinder>
    </link>

    <gazebo reference="wheel_2">
        <material>Gazebo/Black</material>
        <mu1 value="0.2"/>
        <mu2 value="1.5"/>
        <kp value="10000000.0" />
        <kd value="10000.0" />
        <fdir1 value="0 0 1"/>
        <maxContacts value= "1"/>
    </gazebo>

    <!-- WHEEL 3 -->
    <joint name="wheel_3_joint" type="continuous">
        <parent link="base_link"/>
        <child link="wheel_3"/>
        <origin xyz="-0.1 0.1732050808 0" rpy="0 ${pi/2} -${pi/3}"/>
        <axis xyz="0 0 1"/>
    </joint>

    <link name="wheel_3">
        <visual>
            <geometry>      
                <cylinder length="0.038" radius="0.05" />
            </geometry>
            <material name="black"/>
        </visual>
        <collision>
            <geometry>      
                <cylinder length="0.038" radius="0.05" />
            </geometry>
        </collision>
        <xacro:inertial_cylinder mass="0.2" length="0.038" radius="0.05">
            <origin xyz="0 0 0" rpy="0 0 0"/>
        </xacro:inertial_cylinder>
    </link>

    <gazebo reference="wheel_3">
        <material>Gazebo/Black</material>
        <mu1 value="0.2"/>
        <mu2 value="1.5"/>
        <kp value="10000000.0" />
        <kd value="10000.0" />
        <fdir1 value="0 0 1"/>
        <maxContacts value= "1"/>
    </gazebo>

    <!-- Transmissions -->
    <transmission name="tran1">
        <type>transmission_interface/SimpleTransmission</type>
        <joint name="wheel_1_joint">
            <hardwareInterface>hardware_interface/VelocityJointInterface</hardwareInterface>
        </joint>
        <actuator name="motor_1">
            <hardwareInterface>VelocityJointInterface</hardwareInterface>
            <mechanicalReduction>1</mechanicalReduction>
        </actuator>
    </transmission>

    <transmission name="tran2">
        <type>transmission_interface/SimpleTransmission</type>
        <joint name="wheel_2_joint">
            <hardwareInterface>hardware_interface/VelocityJointInterface</hardwareInterface>
        </joint>
        <actuator name="motor_2">
            <hardwareInterface>VelocityJointInterface</hardwareInterface>
            <mechanicalReduction>1</mechanicalReduction>
        </actuator>
    </transmission>

    <transmission name="tran3">
        <type>transmission_interface/SimpleTransmission</type>
        <joint name="wheel_3_joint">
            <hardwareInterface>hardware_interface/VelocityJointInterface</hardwareInterface>
        </joint>
        <actuator name="motor_3">
            <hardwareInterface>VelocityJointInterface</hardwareInterface>
            <mechanicalReduction>1</mechanicalReduction>
        </actuator>
    </transmission>

    <transmission name="tran4">
        <type>transmission_interface/SimpleTransmission</type>
        <joint name="wheel_4_joint">
            <hardwareInterface>hardware_interface/VelocityJointInterface</hardwareInterface>
        </joint>
        <actuator name="motor_4">
            <hardwareInterface>VelocityJointInterface</hardwareInterface>
            <mechanicalReduction>1</mechanicalReduction>
        </actuator>
    </transmission>

    <gazebo>
        <plugin name="gazebo_ros_control" filename="libgazebo_ros_control.so">
        </plugin>
    </gazebo>

</robot>